2022-03-16 21:21:55,303 INFO    MainThread:30002 [wandb_setup.py:_flush():75] Loading settings from /Users/wz/.config/wandb/settings
2022-03-16 21:21:55,303 INFO    MainThread:30002 [wandb_setup.py:_flush():75] Loading settings from /Users/wz/IdeaProjects/context-aware-embedding/Resources/code/wandb/settings
2022-03-16 21:21:55,304 INFO    MainThread:30002 [wandb_setup.py:_flush():75] Loading settings from environment variables: {}
2022-03-16 21:21:55,304 INFO    MainThread:30002 [wandb_setup.py:_flush():75] Inferring run settings from compute environment: {'program': '<python with no main file>'}
2022-03-16 21:21:55,304 INFO    MainThread:30002 [wandb_init.py:_log_setup():405] Logging user logs to /Users/wz/IdeaProjects/context-aware-embedding/Resources/code/wandb/run-20220316_212155-3she8hns/logs/debug.log
2022-03-16 21:21:55,304 INFO    MainThread:30002 [wandb_init.py:_log_setup():406] Logging internal logs to /Users/wz/IdeaProjects/context-aware-embedding/Resources/code/wandb/run-20220316_212155-3she8hns/logs/debug-internal.log
2022-03-16 21:21:55,305 INFO    MainThread:30002 [wandb_init.py:init():439] calling init triggers
2022-03-16 21:21:55,306 INFO    MainThread:30002 [wandb_init.py:init():443] wandb.init called with sweep_config: {}
config: {'lm_name': 'lvwerra/gpt2-imdb', 'ref_lm_name': 'lvwerra/gpt2-imdb', 'cls_model_name': 'lvwerra/distilbert-imdb', 'tk_name': 'gpt2', 'steps': 51200, 'batch_size': 256, 'forward_batch_size': 16, 'ppo_epochs': 4, 'txt_in_len': 5, 'txt_out_len': 20, 'lr': 1.41e-05, 'init_kl_coef': 0.2, 'target': 6, 'horizon': 10000, 'gamma': 1, 'lam': 0.95, 'cliprange': 0.2, 'cliprange_value': 0.2, 'vf_coef': 0.1, 'seed': 1}
2022-03-16 21:21:55,306 INFO    MainThread:30002 [wandb_init.py:init():459] re-initializing run, found existing run on stack: 2w6e26dy
2022-03-16 21:21:55,364 ERROR   MainThread:30002 [wandb_init.py:init():981] error
Traceback (most recent call last):
  File "/opt/anaconda3/lib/python3.7/site-packages/wandb/sdk/wandb_init.py", line 954, in init
    run = wi.init()
  File "/opt/anaconda3/lib/python3.7/site-packages/wandb/sdk/wandb_init.py", line 471, in init
    self._wl._global_run_stack[-1].finish()
  File "/opt/anaconda3/lib/python3.7/site-packages/wandb/sdk/wandb_run.py", line 1538, in finish
    tel.feature.finish = True
  File "/opt/anaconda3/lib/python3.7/site-packages/wandb/sdk/lib/telemetry.py", line 43, in __exit__
    self._run._telemetry_callback(self._obj)
  File "/opt/anaconda3/lib/python3.7/site-packages/wandb/sdk/wandb_run.py", line 470, in _telemetry_callback
    self._telemetry_flush()
  File "/opt/anaconda3/lib/python3.7/site-packages/wandb/sdk/wandb_run.py", line 481, in _telemetry_flush
    self._backend.interface._publish_telemetry(self._telemetry_obj)
  File "/opt/anaconda3/lib/python3.7/site-packages/wandb/sdk/interface/interface_shared.py", line 73, in _publish_telemetry
    self._publish(rec)
  File "/opt/anaconda3/lib/python3.7/site-packages/wandb/sdk/interface/interface_queue.py", line 49, in _publish
    raise Exception("The wandb backend process has shutdown")
Exception: The wandb backend process has shutdown
2022-03-16 21:21:57,421 INFO    MainThread:30002 [wandb_init.py:_pause_backend():318] pausing backend
2022-03-16 21:21:57,421 INFO    MainThread:30002 [jupyter.py:save_ipynb():374] not saving jupyter notebook
2022-03-16 21:21:59,313 INFO    MainThread:30002 [wandb_run.py:_atexit_cleanup():1702] got exitcode: 0
2022-03-16 21:21:59,317 INFO    MainThread:30002 [wandb_run.py:_restore():1674] restore
